Workbook

Sheet Ranking
E2: RANKING DE VENDAS
E3: Franquia Anália Franco
E4: Consórcio Embracon · Porque sonhar não tem limites
C7: META DA FRANQUIA | D7: VENDIDO | E7: % DA META | F7: FALTA VENDER | G7: META POR EQUIPE | K7: INÍCIO DO CICLO | O7: FIM DO CICLO
C8: 21000 | D8: =D46 | E8: =IF(C8>0,D8/C8,0) | F8: =MAX(0,C8-D8) | G8: 7000 | K8: 46296 | O8: 46325
C9: ✎ digite em mil · 21.000 = R$ 21 mi | D9: soma de todas as vendas | E9: =REPT("█",ROUND(MIN(1,E8)*20,0))&REPT("░",20-ROUND(MIN(1,E8)*20,0)) | F9: para fechar a meta | G9: ✎ digite em mil · 7.000 = R$ 7 mi | K9: ✎ opcional | O9: ✎ opcional
C11: EQUIPES | D11: Esquadrão Alpha | E11: Artilheiros | F11: Lekos
C12: =IF(MAX(D12:F12)=0,"Nenhuma venda ainda",INDEX(D11:F11,MATCH(MAX(D12:F12),D12:F12,0))&" na frente") | D12: =SUMIF($F$17:$F$45,D11,$D$17:$D$45) | E12: =SUMIF($F$17:$F$45,E11,$D$17:$D$45) | F12: =SUMIF($F$17:$F$45,F11,$D$17:$D$45)
C13: ="meta de cada equipe: R$ "&TEXT($G$8,"#,##0")&".000" | D13: =IF(D12>=$G$8,"meta batida","faltam R$ "&TEXT($G$8-D12,"#,##0")&".000") | E13: =IF(E12>=$G$8,"meta batida","faltam R$ "&TEXT($G$8-E12,"#,##0")&".000") | F13: =IF(F12>=$G$8,"meta batida","faltam R$ "&TEXT($G$8-F12,"#,##0")&".000")
B15: COMO LANÇAR · Ache o consultor e digite a venda na próxima casinha cinza, em mil: 50 = R$ 50.000 · 300 = R$ 300.000 · 1.000 = R$ 1 milhão. O total, a posição e as equipes se atualizam sozinhos.
B16: # | C16: CONSULTOR | D16: TOTAL VENDIDO | E16: PARTICIPAÇÃO | F16: EQUIPE | G16: 1ª venda | H16: 2ª | I16: 3ª | J16: 4ª | K16: 5ª | L16: 6ª | M16: 7ª | N16: 8ª | O16: 9ª | P16: 10ª | Q16: 11ª | R16: 12ª | S16: 13ª | T16: 14ª | U16: 15ª | V16: 16ª | W16: 17ª | X16: 18ª | Y16: 19ª | Z16: 20ª | AA16: 21ª | AB16: 22ª | AC16: 23ª | AD16: 24ª | AE16: 25ª | AF16: 26ª | AG16: 27ª | AH16: 28ª | AI16: 29ª | AJ16: 30ª
B17: =IF(C17="","",IF(D17=0,"–",RANK(D17,$D$17:$D$45))) | C17: Camily Dias | D17: =IF(C17="","",SUM(G17:AJ17)) | E17: =IF(OR(C17="",$D$46=0),"",REPT("█",ROUND(D17/MAX($D$17:$D$45)*10,0))&REPT("░",10-ROUND(D17/MAX($D$17:$D$45)*10,0))&" "&TEXT(D17/$D$46,"0%")&" do total") | F17: Esquadrão Alpha
B18: =IF(C18="","",IF(D18=0,"–",RANK(D18,$D$17:$D$45))) | C18: Claudia Lino | D18: =IF(C18="","",SUM(G18:AJ18)) | E18: =IF(OR(C18="",$D$46=0),"",REPT("█",ROUND(D18/MAX($D$17:$D$45)*10,0))&REPT("░",10-ROUND(D18/MAX($D$17:$D$45)*10,0))&" "&TEXT(D18/$D$46,"0%")&" do total") | F18: Esquadrão Alpha
B19: =IF(C19="","",IF(D19=0,"–",RANK(D19,$D$17:$D$45))) | C19: Giovana Rodrigues | D19: =IF(C19="","",SUM(G19:AJ19)) | E19: =IF(OR(C19="",$D$46=0),"",REPT("█",ROUND(D19/MAX($D$17:$D$45)*10,0))&REPT("░",10-ROUND(D19/MAX($D$17:$D$45)*10,0))&" "&TEXT(D19/$D$46,"0%")&" do total") | F19: Esquadrão Alpha
B20: =IF(C20="","",IF(D20=0,"–",RANK(D20,$D$17:$D$45))) | C20: Suli Teixeira | D20: =IF(C20="","",SUM(G20:AJ20)) | E20: =IF(OR(C20="",$D$46=0),"",REPT("█",ROUND(D20/MAX($D$17:$D$45)*10,0))&REPT("░",10-ROUND(D20/MAX($D$17:$D$45)*10,0))&" "&TEXT(D20/$D$46,"0%")&" do total") | F20: Esquadrão Alpha
B21: =IF(C21="","",IF(D21=0,"–",RANK(D21,$D$17:$D$45))) | C21: Izabella Nascimento | D21: =IF(C21="","",SUM(G21:AJ21)) | E21: =IF(OR(C21="",$D$46=0),"",REPT("█",ROUND(D21/MAX($D$17:$D$45)*10,0))&REPT("░",10-ROUND(D21/MAX($D$17:$D$45)*10,0))&" "&TEXT(D21/$D$46,"0%")&" do total") | F21: Esquadrão Alpha
B22: =IF(C22="","",IF(D22=0,"–",RANK(D22,$D$17:$D$45))) | C22: Alex Sandro | D22: =IF(C22="","",SUM(G22:AJ22)) | E22: =IF(OR(C22="",$D$46=0),"",REPT("█",ROUND(D22/MAX($D$17:$D$45)*10,0))&REPT("░",10-ROUND(D22/MAX($D$17:$D$45)*10,0))&" "&TEXT(D22/$D$46,"0%")&" do total") | F22: Artilheiros
B23: =IF(C23="","",IF(D23=0,"–",RANK(D23,$D$17:$D$45))) | C23: Edvan Fernandes | D23: =IF(C23="","",SUM(G23:AJ23)) | E23: =IF(OR(C23="",$D$46=0),"",REPT("█",ROUND(D23/MAX($D$17:$D$45)*10,0))&REPT("░",10-ROUND(D23/MAX($D$17:$D$45)*10,0))&" "&TEXT(D23/$D$46,"0%")&" do total") | F23: Artilheiros | G23: 700
B24: =IF(C24="","",IF(D24=0,"–",RANK(D24,$D$17:$D$45))) | C24: Enzo Santorelli | D24: =IF(C24="","",SUM(G24:AJ24)) | E24: =IF(OR(C24="",$D$46=0),"",REPT("█",ROUND(D24/MAX($D$17:$D$45)*10,0))&REPT("░",10-ROUND(D24/MAX($D$17:$D$45)*10,0))&" "&TEXT(D24/$D$46,"0%")&" do total") | F24: Artilheiros
B25: =IF(C25="","",IF(D25=0,"–",RANK(D25,$D$17:$D$45))) | C25: Pedro Lucas | D25: =IF(C25="","",SUM(G25:AJ25)) | E25: =IF(OR(C25="",$D$46=0),"",REPT("█",ROUND(D25/MAX($D$17:$D$45)*10,0))&REPT("░",10-ROUND(D25/MAX($D$17:$D$45)*10,0))&" "&TEXT(D25/$D$46,"0%")&" do total") | F25: Artilheiros
B26: =IF(C26="","",IF(D26=0,"–",RANK(D26,$D$17:$D$45))) | C26: Ricardo Neves | D26: =IF(C26="","",SUM(G26:AJ26)) | E26: =IF(OR(C26="",$D$46=0),"",REPT("█",ROUND(D26/MAX($D$17:$D$45)*10,0))&REPT("░",10-ROUND(D26/MAX($D$17:$D$45)*10,0))&" "&TEXT(D26/$D$46,"0%")&" do total") | F26: Artilheiros | G26: 100
B27: =IF(C27="","",IF(D27=0,"–",RANK(D27,$D$17:$D$45))) | C27: Tamyres Reis | D27: =IF(C27="","",SUM(G27:AJ27)) | E27: =IF(OR(C27="",$D$46=0),"",REPT("█",ROUND(D27/MAX($D$17:$D$45)*10,0))&REPT("░",10-ROUND(D27/MAX($D$17:$D$45)*10,0))&" "&TEXT(D27/$D$46,"0%")&" do total") | F27: Artilheiros | G27: 80 | H27: 60
B28: =IF(C28="","",IF(D28=0,"–",RANK(D28,$D$17:$D$45))) | C28: Bruno Marques | D28: =IF(C28="","",SUM(G28:AJ28)) | E28: =IF(OR(C28="",$D$46=0),"",REPT("█",ROUND(D28/MAX($D$17:$D$45)*10,0))&REPT("░",10-ROUND(D28/MAX($D$17:$D$45)*10,0))&" "&TEXT(D28/$D$46,"0%")&" do total") | F28: Lekos
B29: =IF(C29="","",IF(D29=0,"–",RANK(D29,$D$17:$D$45))) | C29: Matheus Detilio | D29: =IF(C29="","",SUM(G29:AJ29)) | E29: =IF(OR(C29="",$D$46=0),"",REPT("█",ROUND(D29/MAX($D$17:$D$45)*10,0))&REPT("░",10-ROUND(D29/MAX($D$17:$D$45)*10,0))&" "&TEXT(D29/$D$46,"0%")&" do total") | F29: Lekos
B30: =IF(C30="","",IF(D30=0,"–",RANK(D30,$D$17:$D$45))) | C30: Lais Berloni | D30: =IF(C30="","",SUM(G30:AJ30)) | E30: =IF(OR(C30="",$D$46=0),"",REPT("█",ROUND(D30/MAX($D$17:$D$45)*10,0))&REPT("░",10-ROUND(D30/MAX($D$17:$D$45)*10,0))&" "&TEXT(D30/$D$46,"0%")&" do total") | F30: Lekos
B31: =IF(C31="","",IF(D31=0,"–",RANK(D31,$D$17:$D$45))) | C31: Mateus Sales | D31: =IF(C31="","",SUM(G31:AJ31)) | E31: =IF(OR(C31="",$D$46=0),"",REPT("█",ROUND(D31/MAX($D$17:$D$45)*10,0))&REPT("░",10-ROUND(D31/MAX($D$17:$D$45)*10,0))&" "&TEXT(D31/$D$46,"0%")&" do total") | F31: Lekos | G31: 400 | H31: 70
B32: =IF(C32="","",IF(D32=0,"–",RANK(D32,$D$17:$D$45))) | C32: Gabriel Caseri | D32: =IF(C32="","",SUM(G32:AJ32)) | E32: =IF(OR(C32="",$D$46=0),"",REPT("█",ROUND(D32/MAX($D$17:$D$45)*10,0))&REPT("░",10-ROUND(D32/MAX($D$17:$D$45)*10,0))&" "&TEXT(D32/$D$46,"0%")&" do total") | F32: Lekos | G32: 770
B33: =IF(C33="","",IF(D33=0,"–",RANK(D33,$D$17:$D$45))) | C33: Juliana Delgado | D33: =IF(C33="","",SUM(G33:AJ33)) | E33: =IF(OR(C33="",$D$46=0),"",REPT("█",ROUND(D33/MAX($D$17:$D$45)*10,0))&REPT("░",10-ROUND(D33/MAX($D$17:$D$45)*10,0))&" "&TEXT(D33/$D$46,"0%")&" do total") | F33: Lekos | G33: 540
B34: =IF(C34="","",IF(D34=0,"–",RANK(D34,$D$17:$D$45))) | C34: Fernando Kasemodel | D34: =IF(C34="","",SUM(G34:AJ34)) | E34: =IF(OR(C34="",$D$46=0),"",REPT("█",ROUND(D34/MAX($D$17:$D$45)*10,0))&REPT("░",10-ROUND(D34/MAX($D$17:$D$45)*10,0))&" "&TEXT(D34/$D$46,"0%")&" do total") | F34: Lekos
B35: =IF(C35="","",IF(D35=0,"–",RANK(D35,$D$17:$D$45))) | C35: Stephanie Martins | D35: =IF(C35="","",SUM(G35:AJ35)) | E35: =IF(OR(C35="",$D$46=0),"",REPT("█",ROUND(D35/MAX($D$17:$D$45)*10,0))&REPT("░",10-ROUND(D35/MAX($D$17:$D$45)*10,0))&" "&TEXT(D35/$D$46,"0%")&" do total") | F35: Lekos
B36: =IF(C36="","",IF(D36=0,"–",RANK(D36,$D$17:$D$45))) | D36: =IF(C36="","",SUM(G36:AJ36)) | E36: =IF(OR(C36="",$D$46=0),"",REPT("█",ROUND(D36/MAX($D$17:$D$45)*10,0))&REPT("░",10-ROUND(D36/MAX($D$17:$D$45)*10,0))&" "&TEXT(D36/$D$46,"0%")&" do total")
B37: =IF(C37="","",IF(D37=0,"–",RANK(D37,$D$17:$D$45))) | D37: =IF(C37="","",SUM(G37:AJ37)) | E37: =IF(OR(C37="",$D$46=0),"",REPT("█",ROUND(D37/MAX($D$17:$D$45)*10,0))&REPT("░",10-ROUND(D37/MAX($D$17:$D$45)*10,0))&" "&TEXT(D37/$D$46,"0%")&" do total")
B38: =IF(C38="","",IF(D38=0,"–",RANK(D38,$D$17:$D$45))) | D38: =IF(C38="","",SUM(G38:AJ38)) | E38: =IF(OR(C38="",$D$46=0),"",REPT("█",ROUND(D38/MAX($D$17:$D$45)*10,0))&REPT("░",10-ROUND(D38/MAX($D$17:$D$45)*10,0))&" "&TEXT(D38/$D$46,"0%")&" do total")
B39: =IF(C39="","",IF(D39=0,"–",RANK(D39,$D$17:$D$45))) | D39: =IF(C39="","",SUM(G39:AJ39)) | E39: =IF(OR(C39="",$D$46=0),"",REPT("█",ROUND(D39/MAX($D$17:$D$45)*10,0))&REPT("░",10-ROUND(D39/MAX($D$17:$D$45)*10,0))&" "&TEXT(D39/$D$46,"0%")&" do total")
B40: =IF(C40="","",IF(D40=0,"–",RANK(D40,$D$17:$D$45))) | D40: =IF(C40="","",SUM(G40:AJ40)) | E40: =IF(OR(C40="",$D$46=0),"",REPT("█",ROUND(D40/MAX($D$17:$D$45)*10,0))&REPT("░",10-ROUND(D40/MAX($D$17:$D$45)*10,0))&" "&TEXT(D40/$D$46,"0%")&" do total")
B41: =IF(C41="","",IF(D41=0,"–",RANK(D41,$D$17:$D$45))) | D41: =IF(C41="","",SUM(G41:AJ41)) | E41: =IF(OR(C41="",$D$46=0),"",REPT("█",ROUND(D41/MAX($D$17:$D$45)*10,0))&REPT("░",10-ROUND(D41/MAX($D$17:$D$45)*10,0))&" "&TEXT(D41/$D$46,"0%")&" do total")
B42: =IF(C42="","",IF(D42=0,"–",RANK(D42,$D$17:$D$45))) | D42: =IF(C42="","",SUM(G42:AJ42)) | E42: =IF(OR(C42="",$D$46=0),"",REPT("█",ROUND(D42/MAX($D$17:$D$45)*10,0))&REPT("░",10-ROUND(D42/MAX($D$17:$D$45)*10,0))&" "&TEXT(D42/$D$46,"0%")&" do total")
B43: =IF(C43="","",IF(D43=0,"–",RANK(D43,$D$17:$D$45))) | D43: =IF(C43="","",SUM(G43:AJ43)) | E43: =IF(OR(C43="",$D$46=0),"",REPT("█",ROUND(D43/MAX($D$17:$D$45)*10,0))&REPT("░",10-ROUND(D43/MAX($D$17:$D$45)*10,0))&" "&TEXT(D43/$D$46,"0%")&" do total")
B44: =IF(C44="","",IF(D44=0,"–",RANK(D44,$D$17:$D$45))) | D44: =IF(C44="","",SUM(G44:AJ44)) | E44: =IF(OR(C44="",$D$46=0),"",REPT("█",ROUND(D44/MAX($D$17:$D$45)*10,0))&REPT("░",10-ROUND(D44/MAX($D$17:$D$45)*10,0))&" "&TEXT(D44/$D$46,"0%")&" do total")
B45: =IF(C45="","",IF(D45=0,"–",RANK(D45,$D$17:$D$45))) | D45: =IF(C45="","",SUM(G45:AJ45)) | E45: =IF(OR(C45="",$D$46=0),"",REPT("█",ROUND(D45/MAX($D$17:$D$45)*10,0))&REPT("░",10-ROUND(D45/MAX($D$17:$D$45)*10,0))&" "&TEXT(D45/$D$46,"0%")&" do total")
...

Sheet Telão
A1: Consultor | B1: Equipe | C1: Vendido | D1: Venda 1 | E1: Venda 2 | F1: Venda 3 | G1: Venda 4 | H1: Venda 5 | I1: Venda 6 | J1: Venda 7 | K1: Venda 8 | L1: Venda 9 | M1: Venda 10 | N1: Venda 11 | O1: Venda 12 | P1: Venda 13 | Q1: Venda 14 | R1: Venda 15 | S1: Venda 16 | T1: Venda 17 | U1: Venda 18 | V1: Venda 19 | W1: Venda 20 | X1: Venda 21 | Y1: Venda 22 | Z1: Venda 23 | AA1: Venda 24 | AB1: Venda 25 | AC1: Venda 26 | AD1: Venda 27 | AE1: Venda 28 | AF1: Venda 29 | AG1: Venda 30 | AI1: Meta da franquia | AJ1: Meta por equipe | AK1: Início do ciclo | AL1: Fim do ciclo | AN1: Esta aba alimenta o telão sozinha a partir da aba Ranking. Não precisa mexer aqui.
A2: =IF(Ranking!C17="","",Ranking!C17) | B2: =IF(Ranking!C17="","",Ranking!F17) | C2: =IF(Ranking!C17="",0,N(Ranking!D17)*1000) | D2: =IF(Ranking!$C17="",0,N(Ranking!G17)*1000) | E2: =IF(Ranking!$C17="",0,N(Ranking!H17)*1000) | F2: =IF(Ranking!$C17="",0,N(Ranking!I17)*1000) | G2: =IF(Ranking!$C17="",0,N(Ranking!J17)*1000) | H2: =IF(Ranking!$C17="",0,N(Ranking!K17)*1000) | I2: =IF(Ranking!$C17="",0,N(Ranking!L17)*1000) | J2: =IF(Ranking!$C17="",0,N(Ranking!M17)*1000) | K2: =IF(Ranking!$C17="",0,N(Ranking!N17)*1000) | ... AG2: =IF(Ranking!$C17="",0,N(Ranking!AJ17)*1000) | AI2: =N(Ranking!C8)*1000 | AJ2: =N(Ranking!G8)*1000 | AK2: =IF(Ranking!K8="","",Ranking!K8) | AL2: =IF(Ranking!O8="","",Ranking!O8)
A3: =IF(Ranking!C18="","",Ranking!C18) | B3: =IF(Ranking!C18="","",Ranking!F18) | C3: =IF(Ranking!C18="",0,N(Ranking!D18)*1000) | D3: =IF(Ranking!$C18="",0,N(Ranking!G18)*1000) | E3: =IF(Ranking!$C18="",0,N(Ranking!H18)*1000) | F3: =IF(Ranking!$C18="",0,N(Ranking!I18)*1000) | G3: =IF(Ranking!$C18="",0,N(Ranking!J18)*1000) | H3: =IF(Ranking!$C18="",0,N(Ranking!K18)*1000) | I3: =IF(Ranking!$C18="",0,N(Ranking!L18)*1000) | J3: =IF(Ranking!$C18="",0,N(Ranking!M18)*1000) | K3: =IF(Ranking!$C18="",0,N(Ranking!N18)*1000) | ... AG3: =IF(Ranking!$C18="",0,N(Ranking!AJ18)*1000)
A4: =IF(Ranking!C19="","",Ranking!C19) | B4: =IF(Ranking!C19="","",Ranking!F19) | C4: =IF(Ranking!C19="",0,N(Ranking!D19)*1000) | D4: =IF(Ranking!$C19="",0,N(Ranking!G19)*1000) | E4: =IF(Ranking!$C19="",0,N(Ranking!H19)*1000) | F4: =IF(Ranking!$C19="",0,N(Ranking!I19)*1000) | G4: =IF(Ranking!$C19="",0,N(Ranking!J19)*1000) | H4: =IF(Ranking!$C19="",0,N(Ranking!K19)*1000) | I4: =IF(Ranking!$C19="",0,N(Ranking!L19)*1000) | J4: =IF(Ranking!$C19="",0,N(Ranking!M19)*1000) | K4: =IF(Ranking!$C19="",0,N(Ranking!N19)*1000) | ... AG4: =IF(Ranking!$C19="",0,N(Ranking!AJ19)*1000)
A5: =IF(Ranking!C20="","",Ranking!C20) | B5: =IF(Ranking!C20="","",Ranking!F20) | C5: =IF(Ranking!C20="",0,N(Ranking!D20)*1000) | D5: =IF(Ranking!$C20="",0,N(Ranking!G20)*1000) | E5: =IF(Ranking!$C20="",0,N(Ranking!H20)*1000) | F5: =IF(Ranking!$C20="",0,N(Ranking!I20)*1000) | G5: =IF(Ranking!$C20="",0,N(Ranking!J20)*1000) | H5: =IF(Ranking!$C20="",0,N(Ranking!K20)*1000) | I5: =IF(Ranking!$C20="",0,N(Ranking!L20)*1000) | J5: =IF(Ranking!$C20="",0,N(Ranking!M20)*1000) | K5: =IF(Ranking!$C20="",0,N(Ranking!N20)*1000) | ... AG5: =IF(Ranking!$C20="",0,N(Ranking!AJ20)*1000)
A6: =IF(Ranking!C21="","",Ranking!C21) | B6: =IF(Ranking!C21="","",Ranking!F21) | C6: =IF(Ranking!C21="",0,N(Ranking!D21)*1000) | D6: =IF(Ranking!$C21="",0,N(Ranking!G21)*1000) | E6: =IF(Ranking!$C21="",0,N(Ranking!H21)*1000) | F6: =IF(Ranking!$C21="",0,N(Ranking!I21)*1000) | G6: =IF(Ranking!$C21="",0,N(Ranking!J21)*1000) | H6: =IF(Ranking!$C21="",0,N(Ranking!K21)*1000) | I6: =IF(Ranking!$C21="",0,N(Ranking!L21)*1000) | J6: =IF(Ranking!$C21="",0,N(Ranking!M21)*1000) | K6: =IF(Ranking!$C21="",0,N(Ranking!N21)*1000) | ... AG6: =IF(Ranking!$C21="",0,N(Ranking!AJ21)*1000)
A7: =IF(Ranking!C22="","",Ranking!C22) | B7: =IF(Ranking!C22="","",Ranking!F22) | C7: =IF(Ranking!C22="",0,N(Ranking!D22)*1000) | D7: =IF(Ranking!$C22="",0,N(Ranking!G22)*1000) | E7: =IF(Ranking!$C22="",0,N(Ranking!H22)*1000) | F7: =IF(Ranking!$C22="",0,N(Ranking!I22)*1000) | G7: =IF(Ranking!$C22="",0,N(Ranking!J22)*1000) | H7: =IF(Ranking!$C22="",0,N(Ranking!K22)*1000) | I7: =IF(Ranking!$C22="",0,N(Ranking!L22)*1000) | J7: =IF(Ranking!$C22="",0,N(Ranking!M22)*1000) | K7: =IF(Ranking!$C22="",0,N(Ranking!N22)*1000) | ... AG7: =IF(Ranking!$C22="",0,N(Ranking!AJ22)*1000)
A8: =IF(Ranking!C23="","",Ranking!C23) | B8: =IF(Ranking!C23="","",Ranking!F23) | C8: =IF(Ranking!C23="",0,N(Ranking!D23)*1000) | D8: =IF(Ranking!$C23="",0,N(Ranking!G23)*1000) | E8: =IF(Ranking!$C23="",0,N(Ranking!H23)*1000) | F8: =IF(Ranking!$C23="",0,N(Ranking!I23)*1000) | G8: =IF(Ranking!$C23="",0,N(Ranking!J23)*1000) | H8: =IF(Ranking!$C23="",0,N(Ranking!K23)*1000) | I8: =IF(Ranking!$C23="",0,N(Ranking!L23)*1000) | J8: =IF(Ranking!$C23="",0,N(Ranking!M23)*1000) | K8: =IF(Ranking!$C23="",0,N(Ranking!N23)*1000) | ... AG8: =IF(Ranking!$C23="",0,N(Ranking!AJ23)*1000)
A9: =IF(Ranking!C24="","",Ranking!C24) | B9: =IF(Ranking!C24="","",Ranking!F24) | C9: =IF(Ranking!C24="",0,N(Ranking!D24)*1000) | D9: =IF(Ranking!$C24="",0,N(Ranking!G24)*1000) | E9: =IF(Ranking!$C24="",0,N(Ranking!H24)*1000) | F9: =IF(Ranking!$C24="",0,N(Ranking!I24)*1000) | G9: =IF(Ranking!$C24="",0,N(Ranking!J24)*1000) | H9: =IF(Ranking!$C24="",0,N(Ranking!K24)*1000) | I9: =IF(Ranking!$C24="",0,N(Ranking!L24)*1000) | J9: =IF(Ranking!$C24="",0,N(Ranking!M24)*1000) | K9: =IF(Ranking!$C24="",0,N(Ranking!N24)*1000) | ... AG9: =IF(Ranking!$C24="",0,N(Ranking!AJ24)*1000)
A10: =IF(Ranking!C25="","",Ranking!C25) | B10: =IF(Ranking!C25="","",Ranking!F25) | C10: =IF(Ranking!C25="",0,N(Ranking!D25)*1000) | D10: =IF(Ranking!$C25="",0,N(Ranking!G25)*1000) | E10: =IF(Ranking!$C25="",0,N(Ranking!H25)*1000) | F10: =IF(Ranking!$C25="",0,N(Ranking!I25)*1000) | G10: =IF(Ranking!$C25="",0,N(Ranking!J25)*1000) | H10: =IF(Ranking!$C25="",0,N(Ranking!K25)*1000) | I10: =IF(Ranking!$C25="",0,N(Ranking!L25)*1000) | J10: =IF(Ranking!$C25="",0,N(Ranking!M25)*1000) | K10: =IF(Ranking!$C25="",0,N(Ranking!N25)*1000) | ... AG10: =IF(Ranking!$C25="",0,N(Ranking!AJ25)*1000)
A11: =IF(Ranking!C26="","",Ranking!C26) | B11: =IF(Ranking!C26="","",Ranking!F26) | C11: =IF(Ranking!C26="",0,N(Ranking!D26)*1000) | D11: =IF(Ranking!$C26="",0,N(Ranking!G26)*1000) | E11: =IF(Ranking!$C26="",0,N(Ranking!H26)*1000) | F11: =IF(Ranking!$C26="",0,N(Ranking!I26)*1000) | G11: =IF(Ranking!$C26="",0,N(Ranking!J26)*1000) | H11: =IF(Ranking!$C26="",0,N(Ranking!K26)*1000) | I11: =IF(Ranking!$C26="",0,N(Ranking!L26)*1000) | J11: =IF(Ranking!$C26="",0,N(Ranking!M26)*1000) | K11: =IF(Ranking!$C26="",0,N(Ranking!N26)*1000) | ... AG11: =IF(Ranking!$C26="",0,N(Ranking!AJ26)*1000)
A12: =IF(Ranking!C27="","",Ranking!C27) | B12: =IF(Ranking!C27="","",Ranking!F27) | C12: =IF(Ranking!C27="",0,N(Ranking!D27)*1000) | D12: =IF(Ranking!$C27="",0,N(Ranking!G27)*1000) | E12: =IF(Ranking!$C27="",0,N(Ranking!H27)*1000) | F12: =IF(Ranking!$C27="",0,N(Ranking!I27)*1000) | G12: =IF(Ranking!$C27="",0,N(Ranking!J27)*1000) | H12: =IF(Ranking!$C27="",0,N(Ranking!K27)*1000) | I12: =IF(Ranking!$C27="",0,N(Ranking!L27)*1000) | J12: =IF(Ranking!$C27="",0,N(Ranking!M27)*1000) | K12: =IF(Ranking!$C27="",0,N(Ranking!N27)*1000) | ... AG12: =IF(Ranking!$C27="",0,N(Ranking!AJ27)*1000)
A13: =IF(Ranking!C28="","",Ranking!C28) | B13: =IF(Ranking!C28="","",Ranking!F28) | C13: =IF(Ranking!C28="",0,N(Ranking!D28)*1000) | D13: =IF(Ranking!$C28="",0,N(Ranking!G28)*1000) | E13: =IF(Ranking!$C28="",0,N(Ranking!H28)*1000) | F13: =IF(Ranking!$C28="",0,N(Ranking!I28)*1000) | G13: =IF(Ranking!$C28="",0,N(Ranking!J28)*1000) | H13: =IF(Ranking!$C28="",0,N(Ranking!K28)*1000) | I13: =IF(Ranking!$C28="",0,N(Ranking!L28)*1000) | J13: =IF(Ranking!$C28="",0,N(Ranking!M28)*1000) | K13: =IF(Ranking!$C28="",0,N(Ranking!N28)*1000) | ... AG13: =IF(Ranking!$C28="",0,N(Ranking!AJ28)*1000)
A14: =IF(Ranking!C29="","",Ranking!C29) | B14: =IF(Ranking!C29="","",Ranking!F29) | C14: =IF(Ranking!C29="",0,N(Ranking!D29)*1000) | D14: =IF(Ranking!$C29="",0,N(Ranking!G29)*1000) | E14: =IF(Ranking!$C29="",0,N(Ranking!H29)*1000) | F14: =IF(Ranking!$C29="",0,N(Ranking!I29)*1000) | G14: =IF(Ranking!$C29="",0,N(Ranking!J29)*1000) | H14: =IF(Ranking!$C29="",0,N(Ranking!K29)*1000) | I14: =IF(Ranking!$C29="",0,N(Ranking!L29)*1000) | J14: =IF(Ranking!$C29="",0,N(Ranking!M29)*1000) | K14: =IF(Ranking!$C29="",0,N(Ranking!N29)*1000) | ... AG14: =IF(Ranking!$C29="",0,N(Ranking!AJ29)*1000)
... A30: =IF(Ranking!C45="","",Ranking!C45) | B30: =IF(Ranking!C45="","",Ranking!F45) | C30: =IF(Ranking!C45="",0,N(Ranking!D45)*1000) | D30: =IF(Ranking!$C45="",0,N(Ranking!G45)*1000) | E30: =IF(Ranking!$C45="",0,N(Ranking!H45)*1000) | F30: =IF(Ranking!$C45="",0,N(Ranking!I45)*1000) | G30: =IF(Ranking!$C45="",0,N(Ranking!J45)*1000) | H30: =IF(Ranking!$C45="",0,N(Ranking!K45)*1000) | I30: =IF(Ranking!$C45="",0,N(Ranking!L45)*1000) | J30: =IF(Ranking!$C45="",0,N(Ranking!M45)*1000) | K30: =IF(Ranking!$C45="",0,N(Ranking!N45)*1000) | ... AG30: =IF(Ranking!$C45="",0,N(Ranking!AJ45)*1000)
